Workbook
Name Print_Area: 'Справочник типов'!$A$1:$J$27

Sheet Итого по проекту
A1: ПРЕДВАРИТЕЛЬНАЯ ОЦЕНКА СТОИМОСТИ ПРОЕКТА
A3: Ключевые данные для согласования бюджета и подготовки коммерческого предложения
A5: // 01 ПРОЕКТ | G5: // 02 СТОИМОСТЬ ПРОЕКТА
A6: Название | C6: =IF(Ввод!$B$4="","",Ввод!$B$4) | G6: Себестоимость | I6: =SUM(Расчёт!$S$6:$S$55)+SUM('Внешние затраты'!$I$6:$I$25) -> 0
A7: Тип проекта | C7: =IF(Ввод!$B$5="","",IFERROR(VLOOKUP(Ввод!$B$5,'Справочник типов'!$A$2:$C$27,3,0),Ввод!$B$5)) | G7: Цена без НДС, до скидки | I7: =SUM(Расчёт!$R$6:$R$55)+SUM('Внешние затраты'!$J$6:$J$25) -> 0
A8: Дата оценки | C8: =IF(Ввод!$B$6="","",Ввод!$B$6) | G8: Скидка | I8: =Ввод!$B$8 -> 0 | J8: =I7*I8 -> 0
A9: Расчётный срок | C9: =IF(Ввод!$B$5="","",IF(OR(IFERROR(VLOOKUP(Ввод!$B$5,'Справочник типов'!$A$2:$J$27,7,0),"")="Возобновляемая",IFERROR(VLOOKUP(Ввод!$B$5,'Справочник типов'!$A$2:$J$27,8,0),"")="Поддержка"),MAX(1,SUMIF('Технические данные'!$F$12:$F$19,"TERM_MONTHS",'Технические данные'!$I$12:$I$19))&" мес.",ROUNDUP(SUM(Расчёт!$T$6:$T$55)+SUMIF('Технические данные'!$F$12:$F$19,"LEAD_DAYS",'Технические данные'!$I$12:$I$19),0)&" раб. дн.")) | G9: Цена без НДС, со скидкой | I9: =I7-J8 -> 0
A10: Статус расчёта | C10: =Проверки!$B$3 -> ГОТОВ К ЗАПОЛНЕНИЮ | G10: Цена с НДС, со скидкой | I10: =I9*(1+Ввод!$B$7) -> 0
G11: Предварительная оценка: перед коммерческим предложением проверьте состав работ, ставки и внешние затраты.
A13: // 03 СТОИМОСТЬ ПО ЭТАПАМ | H13: // 04 ДОПУЩЕНИЯ И ОГРАНИЧЕНИЯ
A14: № | B14: Этап | C14: Часы | D14: Стоимость без НДС | E14: Срок, раб. дн. | F14: Объяснение этапа | H14: Допущение | J14: Влияние на оценку
A15: =IF(B15="","",ROWS($A$15:A15)) | B15: =IFERROR(INDEX(Расчёт!$B$6:$B$55,MATCH(ROWS($B$15:B15),Расчёт!$A$6:$A$55,0)),"") | C15: =IF(B15="","",SUMIF(Расчёт!$A$6:$A$55,A15,Расчёт!$Q$6:$Q$55)) | D15: =IF(B15="","",SUMIF(Расчёт!$A$6:$A$55,A15,Расчёт!$R$6:$R$55)) | E15: =IF(B15="","",SUMIF(Расчёт!$A$6:$A$55,A15,Расчёт!$T$6:$T$55)) | H15: =IF(Ввод!$B$32="","",Ввод!$B$32) | J15: =IF(Ввод!$D$32="","",Ввод!$D$32)
A16: =IF(B16="","",ROWS($A$15:A16)) | B16: =IFERROR(INDEX(Расчёт!$B$6:$B$55,MATCH(ROWS($B$15:B16),Расчёт!$A$6:$A$55,0)),"") | C16: =IF(B16="","",SUMIF(Расчёт!$A$6:$A$55,A16,Расчёт!$Q$6:$Q$55)) | D16: =IF(B16="","",SUMIF(Расчёт!$A$6:$A$55,A16,Расчёт!$R$6:$R$55)) | E16: =IF(B16="","",SUMIF(Расчёт!$A$6:$A$55,A16,Расчёт!$T$6:$T$55)) | H16: =IF(Ввод!$B$32="","",Ввод!$B$32) | J16: =IF(Ввод!$D$32="","",Ввод!$D$32)
A17: =IF(B17="","",ROWS($A$15:A17)) | B17: =IFERROR(INDEX(Расчёт!$B$6:$B$55,MATCH(ROWS($B$15:B17),Расчёт!$A$6:$A$55,0)),"") | C17: =IF(B17="","",SUMIF(Расчёт!$A$6:$A$55,A17,Расчёт!$Q$6:$Q$55)) | D17: =IF(B17="","",SUMIF(Расчёт!$A$6:$A$55,A17,Расчёт!$R$6:$R$55)) | E17: =IF(B17="","",SUMIF(Расчёт!$A$6:$A$55,A17,Расчёт!$T$6:$T$55)) | H17: =IF(Ввод!$B$32="","",Ввод!$B$32) | J17: =IF(Ввод!$D$32="","",Ввод!$D$32)
A18: =IF(B18="","",ROWS($A$15:A18)) | B18: =IFERROR(INDEX(Расчёт!$B$6:$B$55,MATCH(ROWS($B$15:B18),Расчёт!$A$6:$A$55,0)),"") | C18: =IF(B18="","",SUMIF(Расчёт!$A$6:$A$55,A18,Расчёт!$Q$6:$Q$55)) | D18: =IF(B18="","",SUMIF(Расчёт!$A$6:$A$55,A18,Расчёт!$R$6:$R$55)) | E18: =IF(B18="","",SUMIF(Расчёт!$A$6:$A$55,A18,Расчёт!$T$6:$T$55)) | H18: =IF(Ввод!$B$32="","",Ввод!$B$32) | J18: =IF(Ввод!$D$32="","",Ввод!$D$32)
A19: =IF(B19="","",ROWS($A$15:A19)) | B19: =IFERROR(INDEX(Расчёт!$B$6:$B$55,MATCH(ROWS($B$15:B19),Расчёт!$A$6:$A$55,0)),"") | C19: =IF(B19="","",SUMIF(Расчёт!$A$6:$A$55,A19,Расчёт!$Q$6:$Q$55)) | D19: =IF(B19="","",SUMIF(Расчёт!$A$6:$A$55,A19,Расчёт!$R$6:$R$55)) | E19: =IF(B19="","",SUMIF(Расчёт!$A$6:$A$55,A19,Расчёт!$T$6:$T$55)) | H19: =IF(Ввод!$B$32="","",Ввод!$B$32) | J19: =IF(Ввод!$D$32="","",Ввод!$D$32)
A20: =IF(B20="","",ROWS($A$15:A20)) | B20: =IFERROR(INDEX(Расчёт!$B$6:$B$55,MATCH(ROWS($B$15:B20),Расчёт!$A$6:$A$55,0)),"") | C20: =IF(B20="","",SUMIF(Расчёт!$A$6:$A$55,A20,Расчёт!$Q$6:$Q$55)) | D20: =IF(B20="","",SUMIF(Расчёт!$A$6:$A$55,A20,Расчёт!$R$6:$R$55)) | E20: =IF(B20="","",SUMIF(Расчёт!$A$6:$A$55,A20,Расчёт!$T$6:$T$55)) | H20: =IF(Ввод!$B$32="","",Ввод!$B$32) | J20: =IF(Ввод!$D$32="","",Ввод!$D$32)
A21: =IF(B21="","",ROWS($A$15:A21)) | B21: =IFERROR(INDEX(Расчёт!$B$6:$B$55,MATCH(ROWS($B$15:B21),Расчёт!$A$6:$A$55,0)),"") | C21: =IF(B21="","",SUMIF(Расчёт!$A$6:$A$55,A21,Расчёт!$Q$6:$Q$55)) | D21: =IF(B21="","",SUMIF(Расчёт!$A$6:$A$55,A21,Расчёт!$R$6:$R$55)) | E21: =IF(B21="","",SUMIF(Расчёт!$A$6:$A$55,A21,Расчёт!$T$6:$T$55)) | H21: =IF(Ввод!$B$32="","",Ввод!$B$32) | J21: =IF(Ввод!$D$32="","",Ввод!$D$32)
A22: =IF(B22="","",ROWS($A$15:A22)) | B22: =IFERROR(INDEX(Расчёт!$B$6:$B$55,MATCH(ROWS($B$15:B22),Расчёт!$A$6:$A$55,0)),"") | C22: =IF(B22="","",SUMIF(Расчёт!$A$6:$A$55,A22,Расчёт!$Q$6:$Q$55)) | D22: =IF(B22="","",SUMIF(Расчёт!$A$6:$A$55,A22,Расчёт!$R$6:$R$55)) | E22: =IF(B22="","",SUMIF(Расчёт!$A$6:$A$55,A22,Расчёт!$T$6:$T$55)) | H22: =IF(Ввод!$B$32="","",Ввод!$B$32) | J22: =IF(Ввод!$D$32="","",Ввод!$D$32)

Sheet Ввод
A1: ПАРАМЕТРЫ ПРОЕКТА
A3: // 01 ОСНОВНЫЕ ПАРАМЕТРЫ
A4: Название проекта | D4: Название выводится на итоговый лист.
A5: Тип проекта | D5: Код типа определяет модель и параметры расчёта.
A6: Дата оценки | D6: Дата подготовки оценки.
A7: НДС | B7: 0.22 | D7: Ставка налога для расчёта цены с НДС.
A8: Скидка | B8: 0 | D8: Применяется к клиентской цене без НДС.
A9: Рабочих часов в дне | B9: 8 | D9: Используется для перевода трудозатрат в рабочие дни.
A10: Интерпретация часов ИИ | B10: Авто | D10: Показывает, относятся часы ко всему проекту, месяцу или единице.
A11: Главное допущение
A13: Фиолетовые поля — заполняются пользователем; серые поля — рассчитываются автоматически.
A18: // 02 КЛЮЧЕВЫЕ ПАРАМЕТРЫ ВЫБРАННОГО ТИПА
A19: Параметр | B19: Ед. | C19: Значение по типу | D19: Переопределить | E19: Принятое значение | F19: Назначение
A20: =IFERROR(INDEX('Технические данные'!$B$12:$B$19,MATCH(ROWS($A$20:A20),'Технические данные'!$H$12:$H$19,0)),"") | B20: =IFERROR(INDEX('Технические данные'!$C$12:$C$19,MATCH(ROWS($A$20:A20),'Технические данные'!$H$12:$H$19,0)),"") | C20: =IFERROR(INDEX('Технические данные'!$D$12:$D$19,MATCH(ROWS($A$20:A20),'Технические данные'!$H$12:$H$19,0)),"") | E20: =IF(A20="","",IF(D20<>"",D20,C20)) | F20: =IFERROR(INDEX('Технические данные'!$G$12:$G$19,MATCH(ROWS($A$20:A20),'Технические данные'!$H$12:$H$19,0)),"")
A21: =IFERROR(INDEX('Технические данные'!$B$12:$B$19,MATCH(ROWS($A$20:A21),'Технические данные'!$H$12:$H$19,0)),"") | B21: =IFERROR(INDEX('Технические данные'!$C$12:$C$19,MATCH(ROWS($A$20:A21),'Технические данные'!$H$12:$H$19,0)),"") | C21: =IFERROR(INDEX('Технические данные'!$D$12:$D$19,MATCH(ROWS($A$20:A21),'Технические данные'!$H$12:$H$19,0)),"") | E21: =IF(A21="","",IF(D21<>"",D21,C21)) | F21: =IFERROR(INDEX('Технические данные'!$G$12:$G$19,MATCH(ROWS($A$20:A21),'Технические данные'!$H$12:$H$19,0)),"")
A22: =IFERROR(INDEX('Технические данные'!$B$12:$B$19,MATCH(ROWS($A$20:A22),'Технические данные'!$H$12:$H$19,0)),"") | B22: =IFERROR(INDEX('Технические данные'!$C$12:$C$19,MATCH(ROWS($A$20:A22),'Технические данные'!$H$12:$H$19,0)),"") | C22: =IFERROR(INDEX('Технические данные'!$D$12:$D$19,MATCH(ROWS($A$20:A22),'Технические данные'!$H$12:$H$19,0)),"") | E22: =IF(A22="","",IF(D22<>"",D22,C22)) | F22: =IFERROR(INDEX('Технические данные'!$G$12:$G$19,MATCH(ROWS($A$20:A22),'Технические данные'!$H$12:$H$19,0)),"")
A23: =IFERROR(INDEX('Технические данные'!$B$12:$B$19,MATCH(ROWS($A$20:A23),'Технические данные'!$H$12:$H$19,0)),"") | B23: =IFERROR(INDEX('Технические данные'!$C$12:$C$19,MATCH(ROWS($A$20:A23),'Технические данные'!$H$12:$H$19,0)),"") | C23: =IFERROR(INDEX('Технические данные'!$D$12:$D$19,MATCH(ROWS($A$20:A23),'Технические данные'!$H$12:$H$19,0)),"") | E23: =IF(A23="","",IF(D23<>"",D23,C23)) | F23: =IFERROR(INDEX('Технические данные'!$G$12:$G$19,MATCH(ROWS($A$20:A23),'Технические данные'!$H$12:$H$19,0)),"")
A24: =IFERROR(INDEX('Технические данные'!$B$12:$B$19,MATCH(ROWS($A$20:A24),'Технические данные'!$H$12:$H$19,0)),"") | B24: =IFERROR(INDEX('Технические данные'!$C$12:$C$19,MATCH(ROWS($A$20:A24),'Технические данные'!$H$12:$H$19,0)),"") | C24: =IFERROR(INDEX('Технические данные'!$D$12:$D$19,MATCH(ROWS($A$20:A24),'Технические данные'!$H$12:$H$19,0)),"") | E24: =IF(A24="","",IF(D24<>"",D24,C24)) | F24: =IFERROR(INDEX('Технические данные'!$G$12:$G$19,MATCH(ROWS($A$20:A24),'Технические данные'!$H$12:$H$19,0)),"")
A25: =IFERROR(INDEX('Технические данные'!$B$12:$B$19,MATCH(ROWS($A$20:A25),'Технические данные'!$H$12:$H$19,0)),"") | B25: =IFERROR(INDEX('Технические данные'!$C$12:$C$19,MATCH(ROWS($A$20:A25),'Технические данные'!$H$12:$H$19,0)),"") | C25: =IFERROR(INDEX('Технические данные'!$D$12:$D$19,MATCH(ROWS($A$20:A25),'Технические данные'!$H$12:$H$19,0)),"") | E25: =IF(A25="","",IF(D25<>"",D25,C25)) | F25: =IFERROR(INDEX('Технические данные'!$G$12:$G$19,MATCH(ROWS($A$20:A25),'Технические данные'!$H$12:$H$19,0)),"")
A26: =IFERROR(INDEX('Технические данные'!$B$12:$B$19,MATCH(ROWS($A$20:A26),'Технические данные'!$H$12:$H$19,0)),"") | B26: =IFERROR(INDEX('Технические данные'!$C$12:$C$19,MATCH(ROWS($A$20:A26),'Технические данные'!$H$12:$H$19,0)),"") | C26: =IFERROR(INDEX('Технические данные'!$D$12:$D$19,MATCH(ROWS($A$20:A26),'Технические данные'!$H$12:$H$19,0)),"") | E26: =IF(A26="","",IF(D26<>"",D26,C26)) | F26: =IFERROR(INDEX('Технические данные'!$G$12:$G$19,MATCH(ROWS($A$20:A26),'Технические данные'!$H$12:$H$19,0)),"")
A27: =IFERROR(INDEX('Технические данные'!$B$12:$B$19,MATCH(ROWS($A$20:A27),'Технические данные'!$H$12:$H$19,0)),"") | B27: =IFERROR(INDEX('Технические данные'!$C$12:$C$19,MATCH(ROWS($A$20:A27),'Технические данные'!$H$12:$H$19,0)),"") | C27: =IFERROR(INDEX('Технические данные'!$D$12:$D$19,MATCH(ROWS($A$20:A27),'Технические данные'!$H$12:$H$19,0)),"") | E27: =IF(A27="","",IF(D27<>"",D27,C27)) | F27: =IFERROR(INDEX('Технические данные'!$G$12:$G$19,MATCH(ROWS($A$20:A27),'Технические данные'!$H$12:$H$19,0)),"")
A30: // 03 ДОПУЩЕНИЯ, ВОПРОСЫ И ОГРАНИЧЕНИЯ
A31: Тип | B31: Формулировка | C31: Источник / основание | D31: Влияние на оценку

Sheet Расчёт
A1: Детализация этапов и работ
A3: Синие/жёлтые поля — ввод или переопределение. Формулы извлекают код роли после символа #, поэтому разделитель в названии роли не критичен.
A5: № этапа | B5: Этап | C5: № работы | D5: Работа | E5: Роль | F5: Часы ИИ | G5: Комментарий к часам (ИИ) | H5: База часов | I5: Кол-во (override) | J5: Ставка продажи (override) | K5: Себестоимость (override) | L5: Код роли | M5: Ставка продажи | N5: Себестоимость | O5: Принятая база | P5: Множитель | Q5: Расчётные часы | R5: Цена труда | S5: Себестоимость труда | T5: Экв. раб. дни | U5: Контроль | V5: Площадка / контур | W5: Комментарий / допущение
L6: =IFERROR(MID(E6,FIND("#",E6)+1,20),"") | M6: =IF(D6="","",IF(J6<>"",J6,IFERROR(VLOOKUP(L6,'Справочник ролей'!$A$2:$E$20,4,0),0))) | N6: =IF(D6="","",IF(K6<>"",K6,IFERROR(VLOOKUP(L6,'Справочник ролей'!$A$2:$E$20,5,0),0))) | O6: =IF(D6="","",IF(H6<>"Авто",H6,IF(Ввод!$B$10<>"Авто",Ввод!$B$10,IFERROR(VLOOKUP(Ввод!$B$5,'Справочник типов'!$A$2:$I$27,9,0),"Всего")))) | P6: =IF(D6="","",IF(O6="В месяц",MAX(1,SUMIF('Технические данные'!$F$12:$F$19,"TERM_MONTHS",'Технические данные'!$I$12:$I$19)),IF(O6="На единицу",IF(I6<>"",I6,MAX(1,SUMIF('Технические данные'!$F$12:$F$19,"QTY",'Технические данные'!$I$12:$I$19))),IF(O6="Ед. × месяц",IF(I6<>"",I6,MAX(1,SUMIF('Технические данные'!$F$12:$F$19,"QTY",'Технические данные'!$I$12:$I$19)))*MAX(1,SUMIF('Технические данные'!$F$12:$F$19,"TERM_MONTHS",'Технические данные'!$I$12:$I$19)),1)))) | Q6: =IF(D6="","",F6*P6*IF(SUMIF('Технические данные'!$F$12:$F$19,"COMPLEXITY",'Технические данные'!$I$12:$I$19)=0,1,SUMIF('Технические данные'!$F$12:$F$19,"COMPLEXITY",'Технические данные'!$I$12:$I$19))*(1+SUMIF('Технические данные'!$F$12:$F$19,"RISK_PCT",'Технические данные'!$I$12:$I$19))) | R6: =IF(D6="","",Q6*M6) | S6: =IF(D6="","",Q6*N6) | T6: =IF(D6="","",Q6/(Ввод!$B$9*IF(SUMIF('Технические данные'!$F$12:$F$19,"PARALLEL_FTE",'Технические данные'!$I$12:$I$19)=0,1,SUMIF('Технические данные'!$F$12:$F$19,"PARALLEL_FTE",'Технические данные'!$I$12:$I$19)))) | U6: =IF(D6="","",IF(F6<=0,"ПРОВЕРИТЬ ЧАСЫ",IF(AND(M6=0,N6=0),"ПРОВЕРИТЬ СТАВКУ","OK")))
L7: =IFERROR(MID(E7,FIND("#",E7)+1,20),"") | M7: =IF(D7="","",IF(J7<>"",J7,IFERROR(VLOOKUP(L7,'Справочник ролей'!$A$2:$E$20,4,0),0))) | N7: =IF(D7="","",IF(K7<>"",K7,IFERROR(VLOOKUP(L7,'Справочник ролей'!$A$2:$E$20,5,0),0))) | O7: =IF(D7="","",IF(H7<>"Авто",H7,IF(Ввод!$B$10<>"Авто",Ввод!$B$10,IFERROR(VLOOKUP(Ввод!$B$5,'Справочник типов'!$A$2:$I$27,9,0),"Всего")))) | P7: =IF(D7="","",IF(O7="В месяц",MAX(1,SUMIF('Технические данные'!$F$12:$F$19,"TERM_MONTHS",'Технические данные'!$I$12:$I$19)),IF(O7="На единицу",IF(I7<>"",I7,MAX(1,SUMIF('Технические данные'!$F$12:$F$19,"QTY",'Технические данные'!$I$12:$I$19))),IF(O7="Ед. × месяц",IF(I7<>"",I7,MAX(1,SUMIF('Технические данные'!$F$12:$F$19,"QTY",'Технические данные'!$I$12:$I$19)))*MAX(1,SUMIF('Технические данные'!$F$12:$F$19,"TERM_MONTHS",'Технические данные'!$I$12:$I$19)),1)))) | Q7: =IF(D7="","",F7*P7*IF(SUMIF('Технические данные'!$F$12:$F$19,"COMPLEXITY",'Технические данные'!$I$12:$I$19)=0,1,SUMIF('Технические данные'!$F$12:$F$19,"COMPLEXITY",'Технические данные'!$I$12:$I$19))*(1+SUMIF('Технические данные'!$F$12:$F$19,"RISK_PCT",'Технические данные'!$I$12:$I$19))) | R7: =IF(D7="","",Q7*M7) | S7: =IF(D7="","",Q7*N7) | T7: =IF(D7="","",Q7/(Ввод!$B$9*IF(SUMIF('Технические данные'!$F$12:$F$19,"PARALLEL_FTE",'Технические данные'!$I$12:$I$19)=0,1,SUMIF('Технические данные'!$F$12:$F$19,"PARALLEL_FTE",'Технические данные'!$I$12:$I$19)))) | U7: =IF(D7="","",IF(F7<=0,"ПРОВЕРИТЬ ЧАСЫ",IF(AND(M7=0,N7=0),"ПРОВЕРИТЬ СТАВКУ","OK")))
L8: =IFERROR(MID(E8,FIND("#",E8)+1,20),"") | M8: =IF(D8="","",IF(J8<>"",J8,IFERROR(VLOOKUP(L8,'Справочник ролей'!$A$2:$E$20,4,0),0))) | N8: =IF(D8="","",IF(K8<>"",K8,IFERROR(VLOOKUP(L8,'Справочник ролей'!$A$2:$E$20,5,0),0))) | O8: =IF(D8="","",IF(H8<>"Авто",H8,IF(Ввод!$B$10<>"Авто",Ввод!$B$10,IFERROR(VLOOKUP(Ввод!$B$5,'Справочник типов'!$A$2:$I$27,9,0),"Всего")))) | P8: =IF(D8="","",IF(O8="В месяц",MAX(1,SUMIF('Технические данные'!$F$12:$F$19,"TERM_MONTHS",'Технические данные'!$I$12:$I$19)),IF(O8="На единицу",IF(I8<>"",I8,MAX(1,SUMIF('Технические данные'!$F$12:$F$19,"QTY",'Технические данные'!$I$12:$I$19))),IF(O8="Ед. × месяц",IF(I8<>"",I8,MAX(1,SUMIF('Технические данные'!$F$12:$F$19,"QTY",'Технические данные'!$I$12:$I$19)))*MAX(1,SUMIF('Технические данные'!$F$12:$F$19,"TERM_MONTHS",'Технические данные'!$I$12:$I$19)),1)))) | Q8: =IF(D8="","",F8*P8*IF(SUMIF('Технические данные'!$F$12:$F$19,"COMPLEXITY",'Технические данные'!$I$12:$I$19)=0,1,SUMIF('Технические данные'!$F$12:$F$19,"COMPLEXITY",'Технические данные'!$I$12:$I$19))*(1+SUMIF('Технические данные'!$F$12:$F$19,"RISK_PCT",'Технические данные'!$I$12:$I$19))) | R8: =IF(D8="","",Q8*M8) | S8: =IF(D8="","",Q8*N8) | T8: =IF(D8="","",Q8/(Ввод!$B$9*IF(SUMIF('Технические данные'!$F$12:$F$19,"PARALLEL_FTE",'Технические данные'!$I$12:$I$19)=0,1,SUMIF('Технические данные'!$F$12:$F$19,"PARALLEL_FTE",'Технические данные'!$I$12:$I$19)))) | U8: =IF(D8="","",IF(F8<=0,"ПРОВЕРИТЬ ЧАСЫ",IF(AND(M8=0,N8=0),"ПРОВЕРИТЬ СТАВКУ","OK")))
L9: =IFERROR(MID(E9,FIND("#",E9)+1,20),"") | M9: =IF(D9="","",IF(J9<>"",J9,IFERROR(VLOOKUP(L9,'Справочник ролей'!$A$2:$E$20,4,0),0))) | N9: =IF(D9="","",IF(K9<>"",K9,IFERROR(VLOOKUP(L9,'Справочник ролей'!$A$2:$E$20,5,0),0))) | O9: =IF(D9="","",IF(H9<>"Авто",H9,IF(Ввод!$B$10<>"Авто",Ввод!$B$10,IFERROR(VLOOKUP(Ввод!$B$5,'Справочник типов'!$A$2:$I$27,9,0),"Всего")))) | P9: =IF(D9="","",IF(O9="В месяц",MAX(1,SUMIF('Технические данные'!$F$12:$F$19,"TERM_MONTHS",'Технические данные'!$I$12:$I$19)),IF(O9="На единицу",IF(I9<>"",I9,MAX(1,SUMIF('Технические данные'!$F$12:$F$19,"QTY",'Технические данные'!$I$12:$I$19))),IF(O9="Ед. × месяц",IF(I9<>"",I9,MAX(1,SUMIF('Технические данные'!$F$12:$F$19,"QTY",'Технические данные'!$I$12:$I$19)))*MAX(1,SUMIF('Технические данные'!$F$12:$F$19,"TERM_MONTHS",'Технические данные'!$I$12:$I$19)),1)))) | Q9: =IF(D9="","",F9*P9*IF(SUMIF('Технические данные'!$F$12:$F$19,"COMPLEXITY",'Технические данные'!$I$12:$I$19)=0,1,SUMIF('Технические данные'!$F$12:$F$19,"COMPLEXITY",'Технические данные'!$I$12:$I$19))*(1+SUMIF('Технические данные'!$F$12:$F$19,"RISK_PCT",'Технические данные'!$I$12:$I$19))) | R9: =IF(D9="","",Q9*M9) | S9: =IF(D9="","",Q9*N9) | T9: =IF(D9="","",Q9/(Ввод!$B$9*IF(SUMIF('Технические данные'!$F$12:$F$19,"PARALLEL_FTE",'Технические данные'!$I$12:$I$19)=0,1,SUMIF('Технические данные'!$F$12:$F$19,"PARALLEL_FTE",'Технические данные'!$I$12:$I$19)))) | U9: =IF(D9="","",IF(F9<=0,"ПРОВЕРИТЬ ЧАСЫ",IF(AND(M9=0,N9=0),"ПРОВЕРИТЬ СТАВКУ","OK")))
L10: =IFERROR(MID(E10,FIND("#",E10)+1,20),"") | M10: =IF(D10="","",IF(J10<>"",J10,IFERROR(VLOOKUP(L10,'Справочник ролей'!$A$2:$E$20,4,0),0))) | N10: =IF(D10="","",IF(K10<>"",K10,IFERROR(VLOOKUP(L10,'Справочник ролей'!$A$2:$E$20,5,0),0))) | O10: =IF(D10="","",IF(H10<>"Авто",H10,IF(Ввод!$B$10<>"Авто",Ввод!$B$10,IFERROR(VLOOKUP(Ввод!$B$5,'Справочник типов'!$A$2:$I$27,9,0),"Всего")))) | P10: =IF(D10="","",IF(O10="В месяц",MAX(1,SUMIF('Технические данные'!$F$12:$F$19,"TERM_MONTHS",'Технические данные'!$I$12:$I$19)),IF(O10="На единицу",IF(I10<>"",I10,MAX(1,SUMIF('Технические данные'!$F$12:$F$19,"QTY",'Технические данные'!$I$12:$I$19))),IF(O10="Ед. × месяц",IF(I10<>"",I10,MAX(1,SUMIF('Технические данные'!$F$12:$F$19,"QTY",'Технические данные'!$I$12:$I$19)))*MAX(1,SUMIF('Технические данные'!$F$12:$F$19,"TERM_MONTHS",'Технические данные'!$I$12:$I$19)),1)))) | Q10: =IF(D10="","",F10*P10*IF(SUMIF('Технические данные'!$F$12:$F$19,"COMPLEXITY",'Технические данные'!$I$12:$I$19)=0,1,SUMIF('Технические данные'!$F$12:$F$19,"COMPLEXITY",'Технические данные'!$I$12:$I$19))*(1+SUMIF('Технические данные'!$F$12:$F$19,"RISK_PCT",'Технические данные'!$I$12:$I$19))) | R10: =IF(D10="","",Q10*M10) | S10: =IF(D10="","",Q10*N10) | T10: =IF(D10="","",Q10/(Ввод!$B$9*IF(SUMIF('Технические данные'!$F$12:$F$19,"PARALLEL_FTE",'Технические данные'!$I$12:$I$19)=0,1,SUMIF('Технические данные'!$F$12:$F$19,"PARALLEL_FTE",'Технические данные'!$I$12:$I$19)))) | U10: =IF(D10="","",IF(F10<=0,"ПРОВЕРИТЬ ЧАСЫ",IF(AND(M10=0,N10=0),"ПРОВЕРИТЬ СТАВКУ","OK")))
L11: =IFERROR(MID(E11,FIND("#",E11)+1,20),"") | M11: =IF(D11="","",IF(J11<>"",J11,IFERROR(VLOOKUP(L11,'Справочник ролей'!$A$2:$E$20,4,0),0))) | N11: =IF(D11="","",IF(K11<>"",K11,IFERROR(VLOOKUP(L11,'Справочник ролей'!$A$2:$E$20,5,0),0))) | O11: =IF(D11="","",IF(H11<>"Авто",H11,IF(Ввод!$B$10<>"Авто",Ввод!$B$10,IFERROR(VLOOKUP(Ввод!$B$5,'Справочник типов'!$A$2:$I$27,9,0),"Всего")))) | P11: =IF(D11="","",IF(O11="В месяц",MAX(1,SUMIF('Технические данные'!$F$12:$F$19,"TERM_MONTHS",'Технические данные'!$I$12:$I$19)),IF(O11="На единицу",IF(I11<>"",I11,MAX(1,SUMIF('Технические данные'!$F$12:$F$19,"QTY",'Технические данные'!$I$12:$I$19))),IF(O11="Ед. × месяц",IF(I11<>"",I11,MAX(1,SUMIF('Технические данные'!$F$12:$F$19,"QTY",'Технические данные'!$I$12:$I$19)))*MAX(1,SUMIF('Технические данные'!$F$12:$F$19,"TERM_MONTHS",'Технические данные'!$I$12:$I$19)),1)))) | Q11: =IF(D11="","",F11*P11*IF(SUMIF('Технические данные'!$F$12:$F$19,"COMPLEXITY",'Технические данные'!$I$12:$I$19)=0,1,SUMIF('Технические данные'!$F$12:$F$19,"COMPLEXITY",'Технические данные'!$I$12:$I$19))*(1+SUMIF('Технические данные'!$F$12:$F$19,"RISK_PCT",'Технические данные'!$I$12:$I$19))) | R11: =IF(D11="","",Q11*M11) | S11: =IF(D11="","",Q11*N11) | T11: =IF(D11="","",Q11/(Ввод!$B$9*IF(SUMIF('Технические данные'!$F$12:$F$19,"PARALLEL_FTE",'Технические данные'!$I$12:$I$19)=0,1,SUMIF('Технические данные'!$F$12:$F$19,"PARALLEL_FTE",'Технические данные'!$I$12:$I$19)))) | U11: =IF(D11="","",IF(F11<=0,"ПРОВЕРИТЬ ЧАСЫ",IF(AND(M11=0,N11=0),"ПРОВЕРИТЬ СТАВКУ","OK")))
L12: =IFERROR(MID(E12,FIND("#",E12)+1,20),"") | M12: =IF(D12="","",IF(J12<>"",J12,IFERROR(VLOOKUP(L12,'Справочник ролей'!$A$2:$E$20,4,0),0))) | N12: =IF(D12="","",IF(K12<>"",K12,IFERROR(VLOOKUP(L12,'Справочник ролей'!$A$2:$E$20,5,0),0))) | O12: =IF(D12="","",IF(H12<>"Авто",H12,IF(Ввод!$B$10<>"Авто",Ввод!$B$10,IFERROR(VLOOKUP(Ввод!$B$5,'Справочник типов'!$A$2:$I$27,9,0),"Всего")))) | P12: =IF(D12="","",IF(O12="В месяц",MAX(1,SUMIF('Технические данные'!$F$12:$F$19,"TERM_MONTHS",'Технические данные'!$I$12:$I$19)),IF(O12="На единицу",IF(I12<>"",I12,MAX(1,SUMIF('Технические данные'!$F$12:$F$19,"QTY",'Технические данные'!$I$12:$I$19))),IF(O12="Ед. × месяц",IF(I12<>"",I12,MAX(1,SUMIF('Технические данные'!$F$12:$F$19,"QTY",'Технические данные'!$I$12:$I$19)))*MAX(1,SUMIF('Технические данные'!$F$12:$F$19,"TERM_MONTHS",'Технические данные'!$I$12:$I$19)),1)))) | Q12: =IF(D12="","",F12*P12*IF(SUMIF('Технические данные'!$F$12:$F$19,"COMPLEXITY",'Технические данные'!$I$12:$I$19)=0,1,SUMIF('Технические данные'!$F$12:$F$19,"COMPLEXITY",'Технические данные'!$I$12:$I$19))*(1+SUMIF('Технические данные'!$F$12:$F$19,"RISK_PCT",'Технические данные'!$I$12:$I$19))) | R12: =IF(D12="","",Q12*M12) | S12: =IF(D12="","",Q12*N12) | T12: =IF(D12="","",Q12/(Ввод!$B$9*IF(SUMIF('Технические данные'!$F$12:$F$19,"PARALLEL_FTE",'Технические данные'!$I$12:$I$19)=0,1,SUMIF('Технические данные'!$F$12:$F$19,"PARALLEL_FTE",'Технические данные'!$I$12:$I$19)))) | U12: =IF(D12="","",IF(F12<=0,"ПРОВЕРИТЬ ЧАСЫ",IF(AND(M12=0,N12=0),"ПРОВЕРИТЬ СТАВКУ","OK")))
L13: =IFERROR(MID(E13,FIND("#",E13)+1,20),"") | M13: =IF(D13="","",IF(J13<>"",J13,IFERROR(VLOOKUP(L13,'Справочник ролей'!$A$2:$E$20,4,0),0))) | N13: =IF(D13="","",IF(K13<>"",K13,IFERROR(VLOOKUP(L13,'Справочник ролей'!$A$2:$E$20,5,0),0))) | O13: =IF(D13="","",IF(H13<>"Авто",H13,IF(Ввод!$B$10<>"Авто",Ввод!$B$10,IFERROR(VLOOKUP(Ввод!$B$5,'Справочник типов'!$A$2:$I$27,9,0),"Всего")))) | P13: =IF(D13="","",IF(O13="В месяц",MAX(1,SUMIF('Технические данные'!$F$12:$F$19,"TERM_MONTHS",'Технические данные'!$I$12:$I$19)),IF(O13="На единицу",IF(I13<>"",I13,MAX(1,SUMIF('Технические данные'!$F$12:$F$19,"QTY",'Технические данные'!$I$12:$I$19))),IF(O13="Ед. × месяц",IF(I13<>"",I13,MAX(1,SUMIF('Технические данные'!$F$12:$F$19,"QTY",'Технические данные'!$I$12:$I$19)))*MAX(1,SUMIF('Технические данные'!$F$12:$F$19,"TERM_MONTHS",'Технические данные'!$I$12:$I$19)),1)))) | Q13: =IF(D13="","",F13*P13*IF(SUMIF('Технические данные'!$F$12:$F$19,"COMPLEXITY",'Технические данные'!$I$12:$I$19)=0,1,SUMIF('Технические данные'!$F$12:$F$19,"COMPLEXITY",'Технические данные'!$I$12:$I$19))*(1+SUMIF('Технические данные'!$F$12:$F$19,"RISK_PCT",'Технические данные'!$I$12:$I$19))) | R13: =IF(D13="","",Q13*M13) | S13: =IF(D13="","",Q13*N13) | T13: =IF(D13="","",Q13/(Ввод!$B$9*IF(SUMIF('Технические данные'!$F$12:$F$19,"PARALLEL_FTE",'Технические данные'!$I$12:$I$19)=0,1,SUMIF('Технические данные'!$F$12:$F$19,"PARALLEL_FTE",'Технические данные'!$I$12:$I$19)))) | U13: =IF(D13="","",IF(F13<=0,"ПРОВЕРИТЬ ЧАСЫ",IF(AND(M13=0,N13=0),"ПРОВЕРИТЬ СТАВКУ","OK")))
L14: =IFERROR(MID(E14,FIND("#",E14)+1,20),"") | M14: =IF(D14="","",IF(J14<>"",J14,IFERROR(VLOOKUP(L14,'Справочник ролей'!$A$2:$E$20,4,0),0))) | N14: =IF(D14="","",IF(K14<>"",K14,IFERROR(VLOOKUP(L14,'Справочник ролей'!$A$2:$E$20,5,0),0))) | O14: =IF(D14="","",IF(H14<>"Авто",H14,IF(Ввод!$B$10<>"Авто",Ввод!$B$10,IFERROR(VLOOKUP(Ввод!$B$5,'Справочник типов'!$A$2:$I$27,9,0),"Всего")))) | P14: =IF(D14="","",IF(O14="В месяц",MAX(1,SUMIF('Технические данные'!$F$12:$F$19,"TERM_MONTHS",'Технические данные'!$I$12:$I$19)),IF(O14="На единицу",IF(I14<>"",I14,MAX(1,SUMIF('Технические данные'!$F$12:$F$19,"QTY",'Технические данные'!$I$12:$I$19))),IF(O14="Ед. × месяц",IF(I14<>"",I14,MAX(1,SUMIF('Технические данные'!$F$12:$F$19,"QTY",'Технические данные'!$I$12:$I$19)))*MAX(1,SUMIF('Технические данные'!$F$12:$F$19,"TERM_MONTHS",'Технические данные'!$I$12:$I$19)),1)))) | Q14: =IF(D14="","",F14*P14*IF(SUMIF('Технические данные'!$F$12:$F$19,"COMPLEXITY",'Технические данные'!$I$12:$I$19)=0,1,SUMIF('Технические данные'!$F$12:$F$19,"COMPLEXITY",'Технические данные'!$I$12:$I$19))*(1+SUMIF('Технические данные'!$F$12:$F$19,"RISK_PCT",'Технические данные'!$I$12:$I$19))) | R14: =IF(D14="","",Q14*M14) | S14: =IF(D14="","",Q14*N14) | T14: =IF(D14="","",Q14/(Ввод!$B$9*IF(SUMIF('Технические данные'!$F$12:$F$19,"PARALLEL_FTE",'Технические данные'!$I$12:$I$19)=0,1,SUMIF('Технические данные'!$F$12:$F$19,"PARALLEL_FTE",'Технические данные'!$I$12:$I$19)))) | U14: =IF(D14="","",IF(F14<=0,"ПРОВЕРИТЬ ЧАСЫ",IF(AND(M14=0,N14=0),"ПРОВЕРИТЬ СТАВКУ","OK")))
L15: =IFERROR(MID(E15,FIND("#",E15)+1,20),"") | M15: =IF(D15="","",IF(J15<>"",J15,IFERROR(VLOOKUP(L15,'Справочник ролей'!$A$2:$E$20,4,0),0))) | N15: =IF(D15="","",IF(K15<>"",K15,IFERROR(VLOOKUP(L15,'Справочник ролей'!$A$2:$E$20,5,0),0))) | O15: =IF(D15="","",IF(H15<>"Авто",H15,IF(Ввод!$B$10<>"Авто",Ввод!$B$10,IFERROR(VLOOKUP(Ввод!$B$5,'Справочник типов'!$A$2:$I$27,9,0),"Всего")))) | P15: =IF(D15="","",IF(O15="В месяц",MAX(1,SUMIF('Технические данные'!$F$12:$F$19,"TERM_MONTHS",'Технические данные'!$I$12:$I$19)),IF(O15="На единицу",IF(I15<>"",I15,MAX(1,SUMIF('Технические данные'!$F$12:$F$19,"QTY",'Технические данные'!$I$12:$I$19))),IF(O15="Ед. × месяц",IF(I15<>"",I15,MAX(1,SUMIF('Технические данные'!$F$12:$F$19,"QTY",'Технические данные'!$I$12:$I$19)))*MAX(1,SUMIF('Технические данные'!$F$12:$F$19,"TERM_MONTHS",'Технические данные'!$I$12:$I$19)),1)))) | Q15: =IF(D15="","",F15*P15*IF(SUMIF('Технические данные'!$F$12:$F$19,"COMPLEXITY",'Технические данные'!$I$12:$I$19)=0,1,SUMIF('Технические данные'!$F$12:$F$19,"COMPLEXITY",'Технические данные'!$I$12:$I$19))*(1+SUMIF('Технические данные'!$F$12:$F$19,"RISK_PCT",'Технические данные'!$I$12:$I$19))) | R15: =IF(D15="","",Q15*M15) | S15: =IF(D15="","",Q15*N15) | T15: =IF(D15="","",Q15/(Ввод!$B$9*IF(SUMIF('Технические данные'!$F$12:$F$19,"PARALLEL_FTE",'Технические данные'!$I$12:$I$19)=0,1,SUMIF('Технические данные'!$F$12:$F$19,"PARALLEL_FTE",'Технические данные'!$I$12:$I$19)))) | U15: =IF(D15="","",IF(F15<=0,"ПРОВЕРИТЬ ЧАСЫ",IF(AND(M15=0,N15=0),"ПРОВЕРИТЬ СТАВКУ","OK")))
L16: =IFERROR(MID(E16,FIND("#",E16)+1,20),"") | M16: =IF(D16="","",IF(J16<>"",J16,IFERROR(VLOOKUP(L16,'Справочник ролей'!$A$2:$E$20,4,0),0))) | N16: =IF(D16="","",IF(K16<>"",K16,IFERROR(VLOOKUP(L16,'Справочник ролей'!$A$2:$E$20,5,0),0))) | O16: =IF(D16="","",IF(H16<>"Авто",H16,IF(Ввод!$B$10<>"Авто",Ввод!$B$10,IFERROR(VLOOKUP(Ввод!$B$5,'Справочник типов'!$A$2:$I$27,9,0),"Всего")))) | P16: =IF(D16="","",IF(O16="В месяц",MAX(1,SUMIF('Технические данные'!$F$12:$F$19,"TERM_MONTHS",'Технические данные'!$I$12:$I$19)),IF(O16="На единицу",IF(I16<>"",I16,MAX(1,SUMIF('Технические данные'!$F$12:$F$19,"QTY",'Технические данные'!$I$12:$I$19))),IF(O16="Ед. × месяц",IF(I16<>"",I16,MAX(1,SUMIF('Технические данные'!$F$12:$F$19,"QTY",'Технические данные'!$I$12:$I$19)))*MAX(1,SUMIF('Технические данные'!$F$12:$F$19,"TERM_MONTHS",'Технические данные'!$I$12:$I$19)),1)))) | Q16: =IF(D16="","",F16*P16*IF(SUMIF('Технические данные'!$F$12:$F$19,"COMPLEXITY",'Технические данные'!$I$12:$I$19)=0,1,SUMIF('Технические данные'!$F$12:$F$19,"COMPLEXITY",'Технические данные'!$I$12:$I$19))*(1+SUMIF('Технические данные'!$F$12:$F$19,"RISK_PCT",'Технические данные'!$I$12:$I$19))) | R16: =IF(D16="","",Q16*M16) | S16: =IF(D16="","",Q16*N16) | T16: =IF(D16="","",Q16/(Ввод!$B$9*IF(SUMIF('Технические данные'!$F$12:$F$19,"PARALLEL_FTE",'Технические данные'!$I$12:$I$19)=0,1,SUMIF('Технические данные'!$F$12:$F$19,"PARALLEL_FTE",'Технические данные'!$I$12:$I$19)))) | U16: =IF(D16="","",IF(F16<=0,"ПРОВЕРИТЬ ЧАСЫ",IF(AND(M16=0,N16=0),"ПРОВЕРИТЬ СТАВКУ","OK")))
L17: =IFERROR(MID(E17,FIND("#",E17)+1,20),"") | M17: =IF(D17="","",IF(J17<>"",J17,IFERROR(VLOOKUP(L17,'Справочник ролей'!$A$2:$E$20,4,0),0))) | N17: =IF(D17="","",IF(K17<>"",K17,IFERROR(VLOOKUP(L17,'Справочник ролей'!$A$2:$E$20,5,0),0))) | O17: =IF(D17="","",IF(H17<>"Авто",H17,IF(Ввод!$B$10<>"Авто",Ввод!$B$10,IFERROR(VLOOKUP(Ввод!$B$5,'Справочник типов'!$A$2:$I$27,9,0),"Всего")))) | P17: =IF(D17="","",IF(O17="В месяц",MAX(1,SUMIF('Технические данные'!$F$12:$F$19,"TERM_MONTHS",'Технические данные'!$I$12:$I$19)),IF(O17="На единицу",IF(I17<>"",I17,MAX(1,SUMIF('Технические данные'!$F$12:$F$19,"QTY",'Технические данные'!$I$12:$I$19))),IF(O17="Ед. × месяц",IF(I17<>"",I17,MAX(1,SUMIF('Технические данные'!$F$12:$F$19,"QTY",'Технические данные'!$I$12:$I$19)))*MAX(1,SUMIF('Технические данные'!$F$12:$F$19,"TERM_MONTHS",'Технические данные'!$I$12:$I$19)),1)))) | Q17: =IF(D17="","",F17*P17*IF(SUMIF('Технические данные'!$F$12:$F$19,"COMPLEXITY",'Технические данные'!$I$12:$I$19)=0,1,SUMIF('Технические данные'!$F$12:$F$19,"COMPLEXITY",'Технические данные'!$I$12:$I$19))*(1+SUMIF('Технические данные'!$F$12:$F$19,"RISK_PCT",'Технические данные'!$I$12:$I$19))) | R17: =IF(D17="","",Q17*M17) | S17: =IF(D17="","",Q17*N17) | T17: =IF(D17="","",Q17/(Ввод!$B$9*IF(SUMIF('Технические данные'!$F$12:$F$19,"PARALLEL_FTE",'Технические данные'!$I$12:$I$19)=0,1,SUMIF('Технические данные'!$F$12:$F$19,"PARALLEL_FTE",'Технические данные'!$I$12:$I$19)))) | U17: =IF(D17="","",IF(F17<=0,"ПРОВЕРИТЬ ЧАСЫ",IF(AND(M17=0,N17=0),"ПРОВЕРИТЬ СТАВКУ","OK")))
... L55: =IFERROR(MID(E55,FIND("#",E55)+1,20),"") | M55: =IF(D55="","",IF(J55<>"",J55,IFERROR(VLOOKUP(L55,'Справочник ролей'!$A$2:$E$20,4,0),0))) | N55: =IF(D55="","",IF(K55<>"",K55,IFERROR(VLOOKUP(L55,'Справочник ролей'!$A$2:$E$20,5,0),0))) | O55: =IF(D55="","",IF(H55<>"Авто",H55,IF(Ввод!$B$10<>"Авто",Ввод!$B$10,IFERROR(VLOOKUP(Ввод!$B$5,'Справочник типов'!$A$2:$I$27,9,0),"Всего")))) | P55: =IF(D55="","",IF(O55="В месяц",MAX(1,SUMIF('Технические данные'!$F$12:$F$19,"TERM_MONTHS",'Технические данные'!$I$12:$I$19)),IF(O55="На единицу",IF(I55<>"",I55,MAX(1,SUMIF('Технические данные'!$F$12:$F$19,"QTY",'Технические данные'!$I$12:$I$19))),IF(O55="Ед. × месяц",IF(I55<>"",I55,MAX(1,SUMIF('Технические данные'!$F$12:$F$19,"QTY",'Технические данные'!$I$12:$I$19)))*MAX(1,SUMIF('Технические данные'!$F$12:$F$19,"TERM_MONTHS",'Технические данные'!$I$12:$I$19)),1)))) | Q55: =IF(D55="","",F55*P55*IF(SUMIF('Технические данные'!$F$12:$F$19,"COMPLEXITY",'Технические данные'!$I$12:$I$19)=0,1,SUMIF('Технические данные'!$F$12:$F$19,"COMPLEXITY",'Технические данные'!$I$12:$I$19))*(1+SUMIF('Технические данные'!$F$12:$F$19,"RISK_PCT",'Технические данные'!$I$12:$I$19))) | R55: =IF(D55="","",Q55*M55) | S55: =IF(D55="","",Q55*N55) | T55: =IF(D55="","",Q55/(Ввод!$B$9*IF(SUMIF('Технические данные'!$F$12:$F$19,"PARALLEL_FTE",'Технические данные'!$I$12:$I$19)=0,1,SUMIF('Технические данные'!$F$12:$F$19,"PARALLEL_FTE",'Технические данные'!$I$12:$I$19)))) | U55: =IF(D55="","",IF(F55<=0,"ПРОВЕРИТЬ ЧАСЫ",IF(AND(M55=0,N55=0),"ПРОВЕРИТЬ СТАВКУ","OK")))
K56: =IFERROR(MID(E56,FIND("#",E56)+1,20),"") | R56: =IF(D56="","",Q56*M56)
K57: =IFERROR(MID(E57,FIND("#",E57)+1,20),"") | R57: =IF(D57="","",Q57*M57)
K58: =IFERROR(MID(E58,FIND("#",E58)+1,20),"") | R58: =IF(D58="","",Q58*M58)
K59: =IFERROR(MID(E59,FIND("#",E59)+1,20),"") | R59: =IF(D59="","",Q59*M59)
K60: =IFERROR(MID(E60,FIND("#",E60)+1,20),"") | R60: =IF(D60="","",Q60*M60)
K61: =IFERROR(MID(E61,FIND("#",E61)+1,20),"") | R61: =IF(D61="","",Q61*M61)
K62: =IFERROR(MID(E62,FIND("#",E62)+1,20),"") | R62: =IF(D62="","",Q62*M62)
K63: =IFERROR(MID(E63,FIND("#",E63)+1,20),"") | R63: =IF(D63="","",Q63*M63)
K64: =IFERROR(MID(E64,FIND("#",E64)+1,20),"") | R64: =IF(D64="","",Q64*M64)
K65: =IFERROR(MID(E65,FIND("#",E65)+1,20),"") | R65: =IF(D65="","",Q65*M65)
K66: =IFERROR(MID(E66,FIND("#",E66)+1,20),"") | R66: =IF(D66="","",Q66*M66)
K67: =IFERROR(MID(E67,FIND("#",E67)+1,20),"") | R67: =IF(D67="","",Q67*M67)
... K69: =IFERROR(MID(E69,FIND("#",E69)+1,20),"") | R69: =IF(D69="","",Q69*M69)
K70: =IFERROR(MID(E70,FIND("#",E70)+1,20),"") | Q70: =IF(D70="","",P70*L70) | R70: =IF(D70="","",P70*M70) | T70: =IF(D70="","",IF(F70<=0,"ПРОВЕРИТЬ ЧАСЫ",IF(AND(L70=0,M70=0),"ПРОВЕРИТЬ СТАВКУ","OK")))
K71: =IFERROR(MID(E71,FIND("#",E71)+1,20),"") | Q71: =IF(D71="","",P71*L71) | R71: =IF(D71="","",P71*M71) | T71: =IF(D71="","",IF(F71<=0,"ПРОВЕРИТЬ ЧАСЫ",IF(AND(L71=0,M71=0),"ПРОВЕРИТЬ СТАВКУ","OK")))
K72: =IFERROR(MID(E72,FIND("#",E72)+1,20),"") | Q72: =IF(D72="","",P72*L72) | R72: =IF(D72="","",P72*M72) | T72: =IF(D72="","",IF(F72<=0,"ПРОВЕРИТЬ ЧАСЫ",IF(AND(L72=0,M72=0),"ПРОВЕРИТЬ СТАВКУ","OK")))
K73: =IFERROR(MID(E73,FIND("#",E73)+1,20),"") | Q73: =IF(D73="","",P73*L73) | R73: =IF(D73="","",P73*M73) | T73: =IF(D73="","",IF(F73<=0,"ПРОВЕРИТЬ ЧАСЫ",IF(AND(L73=0,M73=0),"ПРОВЕРИТЬ СТАВКУ","OK")))
K74: =IFERROR(MID(E74,FIND("#",E74)+1,20),"") | Q74: =IF(D74="","",P74*L74) | R74: =IF(D74="","",P74*M74) | T74: =IF(D74="","",IF(F74<=0,"ПРОВЕРИТЬ ЧАСЫ",IF(AND(L74=0,M74=0),"ПРОВЕРИТЬ СТАВКУ","OK")))
K75: =IFERROR(MID(E75,FIND("#",E75)+1,20),"") | Q75: =IF(D75="","",P75*L75) | R75: =IF(D75="","",P75*M75) | T75: =IF(D75="","",IF(F75<=0,"ПРОВЕРИТЬ ЧАСЫ",IF(AND(L75=0,M75=0),"ПРОВЕРИТЬ СТАВКУ","OK")))
K76: =IFERROR(MID(E76,FIND("#",E76)+1,20),"") | Q76: =IF(D76="","",P76*L76) | R76: =IF(D76="","",P76*M76) | T76: =IF(D76="","",IF(F76<=0,"ПРОВЕРИТЬ ЧАСЫ",IF(AND(L76=0,M76=0),"ПРОВЕРИТЬ СТАВКУ","OK")))
K77: =IFERROR(MID(E77,FIND("#",E77)+1,20),"") | Q77: =IF(D77="","",P77*L77) | R77: =IF(D77="","",P77*M77) | T77: =IF(D77="","",IF(F77<=0,"ПРОВЕРИТЬ ЧАСЫ",IF(AND(L77=0,M77=0),"ПРОВЕРИТЬ СТАВКУ","OK")))
K78: =IFERROR(MID(E78,FIND("#",E78)+1,20),"") | Q78: =IF(D78="","",P78*L78) | R78: =IF(D78="","",P78*M78) | T78: =IF(D78="","",IF(F78<=0,"ПРОВЕРИТЬ ЧАСЫ",IF(AND(L78=0,M78=0),"ПРОВЕРИТЬ СТАВКУ","OK")))
K79: =IFERROR(MID(E79,FIND("#",E79)+1,20),"") | Q79: =IF(D79="","",P79*L79) | R79: =IF(D79="","",P79*M79) | T79: =IF(D79="","",IF(F79<=0,"ПРОВЕРИТЬ ЧАСЫ",IF(AND(L79=0,M79=0),"ПРОВЕРИТЬ СТАВКУ","OK")))
K80: =IFERROR(MID(E80,FIND("#",E80)+1,20),"") | Q80: =IF(D80="","",P80*L80) | R80: =IF(D80="","",P80*M80) | T80: =IF(D80="","",IF(F80<=0,"ПРОВЕРИТЬ ЧАСЫ",IF(AND(L80=0,M80=0),"ПРОВЕРИТЬ СТАВКУ","OK")))
...

Sheet Внешние затраты
A1: Провайдеры, лицензии, оборудование и прочие расходы
A3: Если цена продажи за единицу заполнена, она имеет приоритет. Иначе применяется метод выбранного типа: маржа или наценка. Для ежемесячных строк применяется срок договора.
A5: Категория | B5: Описание | C5: Количество | D5: Ед. | E5: Себестоимость за ед. | F5: Цена продажи за ед. (ручная) | G5: Периодичность | H5: Множитель | I5: Итого себестоимость | J5: Итого цена | K5: Комментарий
H6: =IF(B6="","",IF(G6="В месяц",MAX(1,SUMIF('Технические данные'!$F$12:$F$19,"TERM_MONTHS",'Технические данные'!$I$12:$I$19)),1)) | I6: =IF(B6="","",C6*E6*H6) | J6: =IF(B6="","",IF(F6<>"",C6*F6*H6,IF(IFERROR(VLOOKUP(Ввод!$B$5,'Справочник типов'!$A$2:$J$27,10,0),"По наценке")="По марже",IF(SUMIF('Технические данные'!$F$12:$F$19,"TARGET_MARGIN",'Технические данные'!$I$12:$I$19)<1,I6/(1-SUMIF('Технические данные'!$F$12:$F$19,"TARGET_MARGIN",'Технические данные'!$I$12:$I$19)),0),I6*(1+SUMIF('Технические данные'!$F$12:$F$19,"MARKUP",'Технические данные'!$I$12:$I$19)))))
H7: =IF(B7="","",IF(G7="В месяц",MAX(1,SUMIF('Технические данные'!$F$12:$F$19,"TERM_MONTHS",'Технические данные'!$I$12:$I$19)),1)) | I7: =IF(B7="","",C7*E7*H7) | J7: =IF(B7="","",IF(F7<>"",C7*F7*H7,IF(IFERROR(VLOOKUP(Ввод!$B$5,'Справочник типов'!$A$2:$J$27,10,0),"По наценке")="По марже",IF(SUMIF('Технические данные'!$F$12:$F$19,"TARGET_MARGIN",'Технические данные'!$I$12:$I$19)<1,I7/(1-SUMIF('Технические данные'!$F$12:$F$19,"TARGET_MARGIN",'Технические данные'!$I$12:$I$19)),0),I7*(1+SUMIF('Технические данные'!$F$12:$F$19,"MARKUP",'Технические данные'!$I$12:$I$19)))))
H8: =IF(B8="","",IF(G8="В месяц",MAX(1,SUMIF('Технические данные'!$F$12:$F$19,"TERM_MONTHS",'Технические данные'!$I$12:$I$19)),1)) | I8: =IF(B8="","",C8*E8*H8) | J8: =IF(B8="","",IF(F8<>"",C8*F8*H8,IF(IFERROR(VLOOKUP(Ввод!$B$5,'Справочник типов'!$A$2:$J$27,10,0),"По наценке")="По марже",IF(SUMIF('Технические данные'!$F$12:$F$19,"TARGET_MARGIN",'Технические данные'!$I$12:$I$19)<1,I8/(1-SUMIF('Технические данные'!$F$12:$F$19,"TARGET_MARGIN",'Технические данные'!$I$12:$I$19)),0),I8*(1+SUMIF('Технические данные'!$F$12:$F$19,"MARKUP",'Технические данные'!$I$12:$I$19)))))
H9: =IF(B9="","",IF(G9="В месяц",MAX(1,SUMIF('Технические данные'!$F$12:$F$19,"TERM_MONTHS",'Технические данные'!$I$12:$I$19)),1)) | I9: =IF(B9="","",C9*E9*H9) | J9: =IF(B9="","",IF(F9<>"",C9*F9*H9,IF(IFERROR(VLOOKUP(Ввод!$B$5,'Справочник типов'!$A$2:$J$27,10,0),"По наценке")="По марже",IF(SUMIF('Технические данные'!$F$12:$F$19,"TARGET_MARGIN",'Технические данные'!$I$12:$I$19)<1,I9/(1-SUMIF('Технические данные'!$F$12:$F$19,"TARGET_MARGIN",'Технические данные'!$I$12:$I$19)),0),I9*(1+SUMIF('Технические данные'!$F$12:$F$19,"MARKUP",'Технические данные'!$I$12:$I$19)))))
H10: =IF(B10="","",IF(G10="В месяц",MAX(1,SUMIF('Технические данные'!$F$12:$F$19,"TERM_MONTHS",'Технические данные'!$I$12:$I$19)),1)) | I10: =IF(B10="","",C10*E10*H10) | J10: =IF(B10="","",IF(F10<>"",C10*F10*H10,IF(IFERROR(VLOOKUP(Ввод!$B$5,'Справочник типов'!$A$2:$J$27,10,0),"По наценке")="По марже",IF(SUMIF('Технические данные'!$F$12:$F$19,"TARGET_MARGIN",'Технические данные'!$I$12:$I$19)<1,I10/(1-SUMIF('Технические данные'!$F$12:$F$19,"TARGET_MARGIN",'Технические данные'!$I$12:$I$19)),0),I10*(1+SUMIF('Технические данные'!$F$12:$F$19,"MARKUP",'Технические данные'!$I$12:$I$19)))))
H11: =IF(B11="","",IF(G11="В месяц",MAX(1,SUMIF('Технические данные'!$F$12:$F$19,"TERM_MONTHS",'Технические данные'!$I$12:$I$19)),1)) | I11: =IF(B11="","",C11*E11*H11) | J11: =IF(B11="","",IF(F11<>"",C11*F11*H11,IF(IFERROR(VLOOKUP(Ввод!$B$5,'Справочник типов'!$A$2:$J$27,10,0),"По наценке")="По марже",IF(SUMIF('Технические данные'!$F$12:$F$19,"TARGET_MARGIN",'Технические данные'!$I$12:$I$19)<1,I11/(1-SUMIF('Технические данные'!$F$12:$F$19,"TARGET_MARGIN",'Технические данные'!$I$12:$I$19)),0),I11*(1+SUMIF('Технические данные'!$F$12:$F$19,"MARKUP",'Технические данные'!$I$12:$I$19)))))
H12: =IF(B12="","",IF(G12="В месяц",MAX(1,SUMIF('Технические данные'!$F$12:$F$19,"TERM_MONTHS",'Технические данные'!$I$12:$I$19)),1)) | I12: =IF(B12="","",C12*E12*H12) | J12: =IF(B12="","",IF(F12<>"",C12*F12*H12,IF(IFERROR(VLOOKUP(Ввод!$B$5,'Справочник типов'!$A$2:$J$27,10,0),"По наценке")="По марже",IF(SUMIF('Технические данные'!$F$12:$F$19,"TARGET_MARGIN",'Технические данные'!$I$12:$I$19)<1,I12/(1-SUMIF('Технические данные'!$F$12:$F$19,"TARGET_MARGIN",'Технические данные'!$I$12:$I$19)),0),I12*(1+SUMIF('Технические данные'!$F$12:$F$19,"MARKUP",'Технические данные'!$I$12:$I$19)))))
H13: =IF(B13="","",IF(G13="В месяц",MAX(1,SUMIF('Технические данные'!$F$12:$F$19,"TERM_MONTHS",'Технические данные'!$I$12:$I$19)),1)) | I13: =IF(B13="","",C13*E13*H13) | J13: =IF(B13="","",IF(F13<>"",C13*F13*H13,IF(IFERROR(VLOOKUP(Ввод!$B$5,'Справочник типов'!$A$2:$J$27,10,0),"По наценке")="По марже",IF(SUMIF('Технические данные'!$F$12:$F$19,"TARGET_MARGIN",'Технические данные'!$I$12:$I$19)<1,I13/(1-SUMIF('Технические данные'!$F$12:$F$19,"TARGET_MARGIN",'Технические данные'!$I$12:$I$19)),0),I13*(1+SUMIF('Технические данные'!$F$12:$F$19,"MARKUP",'Технические данные'!$I$12:$I$19)))))
H14: =IF(B14="","",IF(G14="В месяц",MAX(1,SUMIF('Технические данные'!$F$12:$F$19,"TERM_MONTHS",'Технические данные'!$I$12:$I$19)),1)) | I14: =IF(B14="","",C14*E14*H14) | J14: =IF(B14="","",IF(F14<>"",C14*F14*H14,IF(IFERROR(VLOOKUP(Ввод!$B$5,'Справочник типов'!$A$2:$J$27,10,0),"По наценке")="По марже",IF(SUMIF('Технические данные'!$F$12:$F$19,"TARGET_MARGIN",'Технические данные'!$I$12:$I$19)<1,I14/(1-SUMIF('Технические данные'!$F$12:$F$19,"TARGET_MARGIN",'Технические данные'!$I$12:$I$19)),0),I14*(1+SUMIF('Технические данные'!$F$12:$F$19,"MARKUP",'Технические данные'!$I$12:$I$19)))))
H15: =IF(B15="","",IF(G15="В месяц",MAX(1,SUMIF('Технические данные'!$F$12:$F$19,"TERM_MONTHS",'Технические данные'!$I$12:$I$19)),1)) | I15: =IF(B15="","",C15*E15*H15) | J15: =IF(B15="","",IF(F15<>"",C15*F15*H15,IF(IFERROR(VLOOKUP(Ввод!$B$5,'Справочник типов'!$A$2:$J$27,10,0),"По наценке")="По марже",IF(SUMIF('Технические данные'!$F$12:$F$19,"TARGET_MARGIN",'Технические данные'!$I$12:$I$19)<1,I15/(1-SUMIF('Технические данные'!$F$12:$F$19,"TARGET_MARGIN",'Технические данные'!$I$12:$I$19)),0),I15*(1+SUMIF('Технические данные'!$F$12:$F$19,"MARKUP",'Технические данные'!$I$12:$I$19)))))
H16: =IF(B16="","",IF(G16="В месяц",MAX(1,SUMIF('Технические данные'!$F$12:$F$19,"TERM_MONTHS",'Технические данные'!$I$12:$I$19)),1)) | I16: =IF(B16="","",C16*E16*H16) | J16: =IF(B16="","",IF(F16<>"",C16*F16*H16,IF(IFERROR(VLOOKUP(Ввод!$B$5,'Справочник типов'!$A$2:$J$27,10,0),"По наценке")="По марже",IF(SUMIF('Технические данные'!$F$12:$F$19,"TARGET_MARGIN",'Технические данные'!$I$12:$I$19)<1,I16/(1-SUMIF('Технические данные'!$F$12:$F$19,"TARGET_MARGIN",'Технические данные'!$I$12:$I$19)),0),I16*(1+SUMIF('Технические данные'!$F$12:$F$19,"MARKUP",'Технические данные'!$I$12:$I$19)))))
H17: =IF(B17="","",IF(G17="В месяц",MAX(1,SUMIF('Технические данные'!$F$12:$F$19,"TERM_MONTHS",'Технические данные'!$I$12:$I$19)),1)) | I17: =IF(B17="","",C17*E17*H17) | J17: =IF(B17="","",IF(F17<>"",C17*F17*H17,IF(IFERROR(VLOOKUP(Ввод!$B$5,'Справочник типов'!$A$2:$J$27,10,0),"По наценке")="По марже",IF(SUMIF('Технические данные'!$F$12:$F$19,"TARGET_MARGIN",'Технические данные'!$I$12:$I$19)<1,I17/(1-SUMIF('Технические данные'!$F$12:$F$19,"TARGET_MARGIN",'Технические данные'!$I$12:$I$19)),0),I17*(1+SUMIF('Технические данные'!$F$12:$F$19,"MARKUP",'Технические данные'!$I$12:$I$19)))))
... H25: =IF(B25="","",IF(G25="В месяц",MAX(1,SUMIF('Технические данные'!$F$12:$F$19,"TERM_MONTHS",'Технические данные'!$I$12:$I$19)),1)) | I25: =IF(B25="","",C25*E25*H25) | J25: =IF(B25="","",IF(F25<>"",C25*F25*H25,IF(IFERROR(VLOOKUP(Ввод!$B$5,'Справочник типов'!$A$2:$J$27,10,0),"По наценке")="По марже",IF(SUMIF('Технические данные'!$F$12:$F$19,"TARGET_MARGIN",'Технические данные'!$I$12:$I$19)<1,I25/(1-SUMIF('Технические данные'!$F$12:$F$19,"TARGET_MARGIN",'Технические данные'!$I$12:$I$19)),0),I25*(1+SUMIF('Технические данные'!$F$12:$F$19,"MARKUP",'Технические данные'!$I$12:$I$19)))))

Sheet Справочник типов
A1: Код типа | B1: Направление | C1: Продукт | D1: Описание | E1: Категория | F1: Ориентир срока, мес. | G1: Тип сделки | H1: Расчётная модель | I1: База часов по умолчанию | J1: Метод внешних затрат
A2: SUP_Complex | B2: DIT | C2: Комплексная поддержка | D2: Комплексное обслуживание ИТ-инфраструктуры | E2: Услуги | F2: 12 | G2: Возобновляемая | H2: Поддержка | I2: В месяц | J2: По наценке
A3: SUP_L1 | B3: DIT | C3: Колл-центр, поддержка | D3: Первая линия и обработка обращений | E3: Услуги | F3: 6 | G3: Разовая | H3: Поддержка | I3: В месяц | J3: По наценке
A4: SUP_L2 | B4: DIT | C4: Поддержка пользователей и рабочих мест | D4: Вторая линия и поддержка рабочих мест | E4: Услуги | F4: 12 | G4: Возобновляемая | H4: Поддержка | I4: В месяц | J4: По наценке
A5: SUP_L3_HW | B5: DIT | C5: Инфраструктура с аппаратной поддержкой | D5: Третья линия и аппаратная поддержка | E5: Услуги | F5: 12 | G5: Возобновляемая | H5: Поддержка | I5: В месяц | J5: По наценке
A6: SUP_L3_SW | B6: DIT | C6: Инфраструктура без аппаратной поддержки | D6: Третья линия без аппаратной поддержки | E6: Услуги | F6: 12 | G6: Возобновляемая | H6: Поддержка | I6: В месяц | J6: По наценке
A7: SUP_SUPPLIER | B7: DIT | C7: Проекты с подрядом | D7: Услуги с существенной долей внешнего подрядчика | E7: Услуги | F7: 12 | G7: Возобновляемая | H7: Подряд | I7: В месяц | J7: По марже
A8: SUP_IT_Audit | B8: DIT | C8: ИТ-аудит | D8: Обследование инфраструктуры и бизнес-процессов | E8: Услуги | F8: 3 | G8: Разовая | H8: Аудит | I8: Всего | J8: По наценке
A9: SUP_IT_Consulting | B9: DIT | C9: ИТ-консалтинг | D9: Архитектура, DR, сети, СРК, мониторинг, регламенты | E9: Услуги | F9: 3 | G9: Разовая | H9: Консалтинг | I9: Всего | J9: По наценке
A10: SUP_IT_Implementation | B10: DIT | C10: Внедрение инфраструктуры | D10: Виртуализация, инфраструктурные сервисы, миграции и обновления | E10: Услуги | F10: 3 | G10: Разовая | H10: Внедрение | I10: Всего | J10: По наценке
A11: SUP_Cloud_Consulting | B11: DIT | C11: Облачный консалтинг | D11: Архитектура, миграции и проектирование облачного решения | E11: Услуги | F11: 3 | G11: Разовая | H11: Консалтинг | I11: Всего | J11: По наценке
A12: SUP_Cloud_IaaS | B12: DIT | C12: Облачные ресурсы IaaS | D12: Продажа облачных ресурсов и сервисов | E12: Cloud | F12: 12 | G12: Возобновляемая | H12: Облако | I12: В месяц | J12: По марже
A13: SUP_Cloud_PaaS | B13: DIT | C13: Облачная платформа PaaS | D13: IaaS, базовые сервисы, лицензии и поддержка | E13: Cloud | F13: 12 | G13: Возобновляемая | H13: Облако | I13: В месяц | J13: По марже
... A27: SEC_Complex | B27: SEC | C27: Комплексная поддержка | D27: Комплексная поддержка решений ИБ | E27: Услуги | F27: 4 | G27: Разовая | H27: Поддержка | I27: В месяц | J27: По наценке

Sheet Параметры типов
A1: Код типа | B1: Слот | C1: Параметр | D1: Ед. | E1: Значение по умолчанию | F1: Обязателен | G1: Код влияния | H1: Как влияет
A2: SUP_Complex | B2: 1 | C2: Пользователей / рабочих мест | D2: шт. | E2: 1 | F2: Да | G2: QTY | H2: Используется для строк «На единицу»
A3: SUP_Complex | B3: 2 | C3: Срок обслуживания | D3: мес. | E3: 12 | F3: Да | G3: TERM_MONTHS | H3: Множитель для ежемесячных работ
A4: SUP_Complex | B4: 3 | C4: Окно поддержки | D4: ч/нед. | E4: 40 | F4: Нет | G4: INFO | H4: Контекст нагрузки и сменности
A5: SUP_Complex | B5: 4 | C5: Обращений / событий в месяц | D5: шт. | F5: Нет | G5: INFO | H5: Контекст нагрузки
A6: SUP_Complex | B6: 5 | C6: SLA реакции | D6: ч | F6: Нет | G6: INFO | H6: Контекст уровня сервиса
A7: SUP_Complex | B7: 6 | C7: Параллельная команда | D7: FTE | E7: 1 | F7: Да | G7: PARALLEL_FTE | H7: Оценка календарной нагрузки
A8: SUP_Complex | B8: 7 | C8: Резерв рисков | D8: % | E8: 0 | F8: Нет | G8: RISK_PCT | H8: Добавляется к трудозатратам
A9: SUP_Complex | B9: 8 | C9: Наценка внешних затрат | D9: % | E9: 0 | F9: Нет | G9: MARKUP | H9: Применяется при отсутствии ручной цены
A10: SUP_L1 | B10: 1 | C10: Пользователей / абонентов | D10: шт. | E10: 1 | F10: Да | G10: QTY | H10: Используется для строк «На единицу»
A11: SUP_L1 | B11: 2 | C11: Срок обслуживания | D11: мес. | E11: 6 | F11: Да | G11: TERM_MONTHS | H11: Множитель для ежемесячных работ
A12: SUP_L1 | B12: 3 | C12: Окно поддержки | D12: ч/нед. | E12: 40 | F12: Нет | G12: INFO | H12: Контекст нагрузки и сменности
A13: SUP_L1 | B13: 4 | C13: Обращений / событий в месяц | D13: шт. | F13: Нет | G13: INFO | H13: Контекст нагрузки
A14: SUP_L1 | B14: 5 | C14: SLA реакции | D14: ч | F14: Нет | G14: INFO | H14: Контекст уровня сервиса
A15: SUP_L1 | B15: 6 | C15: Параллельная команда | D15: FTE | E15: 1 | F15: Да | G15: PARALLEL_FTE | H15: Оценка календарной нагрузки
A16: SUP_L1 | B16: 7 | C16: Резерв рисков | D16: % | E16: 0 | F16: Нет | G16: RISK_PCT | H16: Добавляется к трудозатратам
A17: SUP_L1 | B17: 8 | C17: Наценка внешних затрат | D17: % | E17: 0 | F17: Нет | G17: MARKUP | H17: Применяется при отсутствии ручной цены
A18: SUP_L2 | B18: 1 | C18: Рабочих мест | D18: шт. | E18: 1 | F18: Да | G18: QTY | H18: Используется для строк «На единицу»
A19: SUP_L2 | B19: 2 | C19: Срок обслуживания | D19: мес. | E19: 12 | F19: Да | G19: TERM_MONTHS | H19: Множитель для ежемесячных работ
A20: SUP_L2 | B20: 3 | C20: Окно поддержки | D20: ч/нед. | E20: 40 | F20: Нет | G20: INFO | H20: Контекст нагрузки и сменности
A21: SUP_L2 | B21: 4 | C21: Обращений / событий в месяц | D21: шт. | F21: Нет | G21: INFO | H21: Контекст нагрузки
A22: SUP_L2 | B22: 5 | C22: SLA реакции | D22: ч | F22: Нет | G22: INFO | H22: Контекст уровня сервиса
A23: SUP_L2 | B23: 6 | C23: Параллельная команда | D23: FTE | E23: 1 | F23: Да | G23: PARALLEL_FTE | H23: Оценка календарной нагрузки
A24: SUP_L2 | B24: 7 | C24: Резерв рисков | D24: % | E24: 0 | F24: Нет | G24: RISK_PCT | H24: Добавляется к трудозатратам
A25: SUP_L2 | B25: 8 | C25: Наценка внешних затрат | D25: % | E25: 0 | F25: Нет | G25: MARKUP | H25: Применяется при отсутствии ручной цены
A26: SUP_L3_HW | B26: 1 | C26: Единиц оборудования | D26: шт. | E26: 1 | F26: Да | G26: QTY | H26: Используется для строк «На единицу»
A27: SUP_L3_HW | B27: 2 | C27: Срок обслуживания | D27: мес. | E27: 12 | F27: Да | G27: TERM_MONTHS | H27: Множитель для ежемесячных работ
A28: SUP_L3_HW | B28: 3 | C28: Окно поддержки | D28: ч/нед. | E28: 40 | F28: Нет | G28: INFO | H28: Контекст нагрузки и сменности
A29: SUP_L3_HW | B29: 4 | C29: Обращений / событий в месяц | D29: шт. | F29: Нет | G29: INFO | H29: Контекст нагрузки
A30: SUP_L3_HW | B30: 5 | C30: SLA реакции | D30: ч | F30: Нет | G30: INFO | H30: Контекст уровня сервиса
A31: SUP_L3_HW | B31: 6 | C31: Параллельная команда | D31: FTE | E31: 1 | F31: Да | G31: PARALLEL_FTE | H31: Оценка календарной нагрузки
A32: SUP_L3_HW | B32: 7 | C32: Резерв рисков | D32: % | E32: 0 | F32: Нет | G32: RISK_PCT | H32: Добавляется к трудозатратам
A33: SUP_L3_HW | B33: 8 | C33: Наценка внешних затрат | D33: % | E33: 0 | F33: Нет | G33: MARKUP | H33: Применяется при отсутствии ручной цены
A34: SUP_L3_SW | B34: 1 | C34: Серверов / систем | D34: шт. | E34: 1 | F34: Да | G34: QTY | H34: Используется для строк «На единицу»
A35: SUP_L3_SW | B35: 2 | C35: Срок обслуживания | D35: мес. | E35: 12 | F35: Да | G35: TERM_MONTHS | H35: Множитель для ежемесячных работ
A36: SUP_L3_SW | B36: 3 | C36: Окно поддержки | D36: ч/нед. | E36: 40 | F36: Нет | G36: INFO | H36: Контекст нагрузки и сменности
A37: SUP_L3_SW | B37: 4 | C37: Обращений / событий в месяц | D37: шт. | F37: Нет | G37: INFO | H37: Контекст нагрузки
A38: SUP_L3_SW | B38: 5 | C38: SLA реакции | D38: ч | F38: Нет | G38: INFO | H38: Контекст уровня сервиса
A39: SUP_L3_SW | B39: 6 | C39: Параллельная команда | D39: FTE | E39: 1 | F39: Да | G39: PARALLEL_FTE | H39: Оценка календарной нагрузки
A40: SUP_L3_SW | B40: 7 | C40: Резерв рисков | D40: % | E40: 0 | F40: Нет | G40: RISK_PCT | H40: Добавляется к трудозатратам
...

Sheet Справочник ролей
A1: Код роли | B1: Направление | C1: Роль | D1: Ставка продажи, руб./ч | E1: Себестоимость, руб./ч | G1: Направление | H1: Средняя ставка продажи | I1: Средняя себестоимость
A2: 6034 | B2: SEC | C2: Тимлид-Архитектор ИБ | #6034 | D2: 7500 | E2: 6506 | G2: SEC | H2: 5975 | I2: 5384
A3: 6035 | B3: SEC | C3: Ведущий инженер ИБ | #6035 | D3: 5500 | E3: 4566 | G3: DIT / SUPP | H3: 3466 | I3: 2914
A4: 6036 | B4: SEC | C4: Пентестер | #6036 | D4: 5500 | E4: 5200 | G4: Примечание | H4: Средние значения сохранены справочно | I4: В строках расчёта используются ставки конкретных ролей
A5: 6037 | B5: SEC | C5: Ведущий Архитектор ИБ | #6037 | D5: 6500 | E5: 5559
A6: 6039 | B6: SEC | C6: Архитектор ИБ | #6039 | D6: 5850 | E6: 4905
A7: 472 | B7: DIT | C7: Руководитель дежурной смены | #472 | D7: 4500 | E7: 4169
A8: 473 | B8: DIT | C8: Супервизор - Руководитель группы | #473 | D8: 2500 | E8: 1745
A9: 474 | B9: DIT | C9: L1 Инженер дежурной смены | #474 | D9: 2100 | E9: 1424
A10: 475 | B10: DIT | C10: L2 Инженер технической поддержки | #475 | D10: 3000 | E10: 2203
A11: 476 | B11: DIT | C11: Руководитель 3 линии | #476 | D11: 5800 | E11: 5609
A12: 477 | B12: DIT | C12: Тимлид - Руководитель группы | #477 | D12: 5800 | E12: 5196
A13: 478 | B13: DIT | C13: L3 Сетевой инженер | #478 | D13: 4200 | E13: 3380
A14: 479 | B14: DIT | C14: L3 Windows инженер | #479 | D14: 4200 | E14: 3736
A15: 480 | B15: DIT | C15: L3 Архитектор | #480 | D15: 6500 | E15: 5695
A16: 1202 | B16: DIT | C16: L3 DevOps-инженер | #1202 | D16: 4200 | E16: 2755
... A20: 1207 | B20: DIT | C20: L3 DBA инженер | #1207 | D20: 4200 | E20: 2755

Sheet Проверки
A1: Контроли модели
A3: MODEL STATUS | B3: =IF(Ввод!$B$5="","ГОТОВ К ЗАПОЛНЕНИЮ",IF(COUNTIF(E6:E13,"FAIL")>0,"FAIL","PASS")) -> ГОТОВ К ЗАПОЛНЕНИЮ
A5: Проверка | B5: Дельта / значение | C5: Где исправить | D5: Примечание | E5: Статус
A6: Тип проекта распознан | B6: =IF(ISNUMBER(MATCH(Ввод!$B$5,'Справочник типов'!$A$2:$A$27,0)),1,0) -> 0 | C6: Ввод!B5 | D6: Должно быть 1 | E6: =IF(B6=1,"PASS","FAIL") -> FAIL
A7: Строки с отсутствующей ставкой | B7: =COUNTIF(Расчёт!$U$6:$U$55,"*СТАВКУ*") -> 0 | C7: Расчёт!M:N | D7: 0 либо ручные ставки | E7: =IF(B7=0,"PASS","FAIL") -> PASS
A8: Строки с некорректными часами | B8: =COUNTIF(Расчёт!$U$6:$U$55,"*ЧАСЫ*") -> 0 | C8: Расчёт!F:F | D8: Должно быть 0 | E8: =IF(B8=0,"PASS","FAIL") -> PASS
A9: Незаполненные обязательные параметры | B9: =COUNTIFS('Технические данные'!$E$12:$E$19,"Да",'Технические данные'!$I$12:$I$19,"") -> 0 | C9: Технические данные!I12:I19 | D9: Должно быть 0 | E9: =IF(B9=0,"PASS","FAIL") -> PASS
A10: Срок для ежемесячных строк | B10: =IF(COUNTIF(Расчёт!$O$6:$O$105,"*месяц*")+COUNTIFS('Внешние затраты'!$G$6:$G$25,"В месяц",'Внешние затраты'!$I$6:$I$25,">0")=0,1,SUMIF('Технические данные'!$F$12:$F$19,"TERM_MONTHS",'Технические данные'!$I$12:$I$19)) -> 1 | C10: Ключевые параметры: срок | D10: Должен быть > 0 при ежемесячных строках | E10: =IF(B10>0,"PASS","FAIL") -> PASS
A11: Маржа внешних затрат | B11: =IF(AND(IFERROR(VLOOKUP(Ввод!$B$5,'Справочник типов'!$A$2:$J$27,10,0),"")="По марже",SUM('Внешние затраты'!$I$6:$I$25)>0),SUMIF('Технические данные'!$F$12:$F$19,"TARGET_MARGIN",'Технические данные'!$I$12:$I$19),0.01) -> 0.01 | C11: Ключевые параметры: маржа | D11: 0 < маржа < 95% при наличии внешних затрат | E11: =IF(AND(B11>0,B11<0.95),"PASS","FAIL") -> PASS
A12: Рабочих часов в дне | B12: =Ввод!$B$9 -> 8 | C12: Ввод!B9 | D12: Должно быть > 0 | E12: =IF(B12>0,"PASS","FAIL") -> PASS
A13: Строки с отрицательными исходными часами | B13: =COUNTIF(Расчёт!$F$6:$F$55,"<0") -> 0 | C13: Расчёт!F:F | D13: Должно быть 0 | E13: =IF(B13=0,"PASS","FAIL") -> PASS

Sheet Технические данные
A1: Технические данные и служебные параметры
A3: Архив параметров, исключённых из пользовательского ввода | D3: Параметры выбранного типа
A4: Режим оценки | B4: Бюджетная | D4: Направление | E4: =IFERROR(VLOOKUP(Ввод!$B$5,'Справочник типов'!$A$2:$J$27,2,0),"") | F4: Классификация проекта
A5: Уверенность оценки | D5: Продукт | E5: =IFERROR(VLOOKUP(Ввод!$B$5,'Справочник типов'!$A$2:$J$27,3,0),"") | F5: Пользовательское название типа
A6: Плановая дата старта | D6: Расчётная модель | E6: =IFERROR(VLOOKUP(Ввод!$B$5,'Справочник типов'!$A$2:$J$27,8,0),"") | F6: Логика расчёта
A7: Источник / версия ТЗ | D7: Категория | E7: =IFERROR(VLOOKUP(Ввод!$B$5,'Справочник типов'!$A$2:$J$27,5,0),"") | F7: Категория предложения
A8: Коммерческий резерв (исключён из цены) | B8: 0 | D8: Типовой срок, мес. | E8: =IFERROR(VLOOKUP(Ввод!$B$5,'Справочник типов'!$A$2:$J$27,6,0),"") | F8: Справочный срок
D9: Тип сделки | E9: =IFERROR(VLOOKUP(Ввод!$B$5,'Справочник типов'!$A$2:$J$27,7,0),"") | F9: Разовая или возобновляемая модель
A10: Полный набор параметров выбранного типа | D10: База часов по умолчанию | E10: =IFERROR(VLOOKUP(Ввод!$B$5,'Справочник типов'!$A$2:$J$27,9,0),"") | F10: Интерпретация часов
A11: Слот | B11: Параметр | C11: Ед. | D11: Значение по типу | E11: Обязателен | F11: Код влияния | G11: Логика | H11: № на форме | I11: Принятое значение
A12: 1 | B12: =IFERROR(INDEX('Параметры типов'!$C$2:$C$209,(MATCH(Ввод!$B$5,'Справочник типов'!$A$2:$A$27,0)-1)*8+$A12),"") | C12: =IFERROR(INDEX('Параметры типов'!$D$2:$D$209,(MATCH(Ввод!$B$5,'Справочник типов'!$A$2:$A$27,0)-1)*8+$A12),"") | D12: =IFERROR(INDEX('Параметры типов'!$E$2:$E$209,(MATCH(Ввод!$B$5,'Справочник типов'!$A$2:$A$27,0)-1)*8+$A12),"") | E12: =IFERROR(INDEX('Параметры типов'!$F$2:$F$209,(MATCH(Ввод!$B$5,'Справочник типов'!$A$2:$A$27,0)-1)*8+$A12),"") | F12: =IFERROR(INDEX('Параметры типов'!$G$2:$G$209,(MATCH(Ввод!$B$5,'Справочник типов'!$A$2:$A$27,0)-1)*8+$A12),"") | G12: =IFERROR(INDEX('Параметры типов'!$H$2:$H$209,(MATCH(Ввод!$B$5,'Справочник типов'!$A$2:$A$27,0)-1)*8+$A12),"") | H12: =IF(AND(F12<>"",F12<>"INFO"),COUNTIFS($F$12:F12,"<>INFO",$F$12:F12,"<>"),"") | I12: =IFERROR(INDEX(Ввод!$E$20:$E$27,MATCH(B12,Ввод!$A$20:$A$27,0)),D12)
A13: 2 | B13: =IFERROR(INDEX('Параметры типов'!$C$2:$C$209,(MATCH(Ввод!$B$5,'Справочник типов'!$A$2:$A$27,0)-1)*8+$A13),"") | C13: =IFERROR(INDEX('Параметры типов'!$D$2:$D$209,(MATCH(Ввод!$B$5,'Справочник типов'!$A$2:$A$27,0)-1)*8+$A13),"") | D13: =IFERROR(INDEX('Параметры типов'!$E$2:$E$209,(MATCH(Ввод!$B$5,'Справочник типов'!$A$2:$A$27,0)-1)*8+$A13),"") | E13: =IFERROR(INDEX('Параметры типов'!$F$2:$F$209,(MATCH(Ввод!$B$5,'Справочник типов'!$A$2:$A$27,0)-1)*8+$A13),"") | F13: =IFERROR(INDEX('Параметры типов'!$G$2:$G$209,(MATCH(Ввод!$B$5,'Справочник типов'!$A$2:$A$27,0)-1)*8+$A13),"") | G13: =IFERROR(INDEX('Параметры типов'!$H$2:$H$209,(MATCH(Ввод!$B$5,'Справочник типов'!$A$2:$A$27,0)-1)*8+$A13),"") | H13: =IF(AND(F13<>"",F13<>"INFO"),COUNTIFS($F$12:F13,"<>INFO",$F$12:F13,"<>"),"") | I13: =IFERROR(INDEX(Ввод!$E$20:$E$27,MATCH(B13,Ввод!$A$20:$A$27,0)),D13)
A14: 3 | B14: =IFERROR(INDEX('Параметры типов'!$C$2:$C$209,(MATCH(Ввод!$B$5,'Справочник типов'!$A$2:$A$27,0)-1)*8+$A14),"") | C14: =IFERROR(INDEX('Параметры типов'!$D$2:$D$209,(MATCH(Ввод!$B$5,'Справочник типов'!$A$2:$A$27,0)-1)*8+$A14),"") | D14: =IFERROR(INDEX('Параметры типов'!$E$2:$E$209,(MATCH(Ввод!$B$5,'Справочник типов'!$A$2:$A$27,0)-1)*8+$A14),"") | E14: =IFERROR(INDEX('Параметры типов'!$F$2:$F$209,(MATCH(Ввод!$B$5,'Справочник типов'!$A$2:$A$27,0)-1)*8+$A14),"") | F14: =IFERROR(INDEX('Параметры типов'!$G$2:$G$209,(MATCH(Ввод!$B$5,'Справочник типов'!$A$2:$A$27,0)-1)*8+$A14),"") | G14: =IFERROR(INDEX('Параметры типов'!$H$2:$H$209,(MATCH(Ввод!$B$5,'Справочник типов'!$A$2:$A$27,0)-1)*8+$A14),"") | H14: =IF(AND(F14<>"",F14<>"INFO"),COUNTIFS($F$12:F14,"<>INFO",$F$12:F14,"<>"),"") | I14: =IFERROR(INDEX(Ввод!$E$20:$E$27,MATCH(B14,Ввод!$A$20:$A$27,0)),D14)
A15: 4 | B15: =IFERROR(INDEX('Параметры типов'!$C$2:$C$209,(MATCH(Ввод!$B$5,'Справочник типов'!$A$2:$A$27,0)-1)*8+$A15),"") | C15: =IFERROR(INDEX('Параметры типов'!$D$2:$D$209,(MATCH(Ввод!$B$5,'Справочник типов'!$A$2:$A$27,0)-1)*8+$A15),"") | D15: =IFERROR(INDEX('Параметры типов'!$E$2:$E$209,(MATCH(Ввод!$B$5,'Справочник типов'!$A$2:$A$27,0)-1)*8+$A15),"") | E15: =IFERROR(INDEX('Параметры типов'!$F$2:$F$209,(MATCH(Ввод!$B$5,'Справочник типов'!$A$2:$A$27,0)-1)*8+$A15),"") | F15: =IFERROR(INDEX('Параметры типов'!$G$2:$G$209,(MATCH(Ввод!$B$5,'Справочник типов'!$A$2:$A$27,0)-1)*8+$A15),"") | G15: =IFERROR(INDEX('Параметры типов'!$H$2:$H$209,(MATCH(Ввод!$B$5,'Справочник типов'!$A$2:$A$27,0)-1)*8+$A15),"") | H15: =IF(AND(F15<>"",F15<>"INFO"),COUNTIFS($F$12:F15,"<>INFO",$F$12:F15,"<>"),"") | I15: =IFERROR(INDEX(Ввод!$E$20:$E$27,MATCH(B15,Ввод!$A$20:$A$27,0)),D15)
A16: 5 | B16: =IFERROR(INDEX('Параметры типов'!$C$2:$C$209,(MATCH(Ввод!$B$5,'Справочник типов'!$A$2:$A$27,0)-1)*8+$A16),"") | C16: =IFERROR(INDEX('Параметры типов'!$D$2:$D$209,(MATCH(Ввод!$B$5,'Справочник типов'!$A$2:$A$27,0)-1)*8+$A16),"") | D16: =IFERROR(INDEX('Параметры типов'!$E$2:$E$209,(MATCH(Ввод!$B$5,'Справочник типов'!$A$2:$A$27,0)-1)*8+$A16),"") | E16: =IFERROR(INDEX('Параметры типов'!$F$2:$F$209,(MATCH(Ввод!$B$5,'Справочник типов'!$A$2:$A$27,0)-1)*8+$A16),"") | F16: =IFERROR(INDEX('Параметры типов'!$G$2:$G$209,(MATCH(Ввод!$B$5,'Справочник типов'!$A$2:$A$27,0)-1)*8+$A16),"") | G16: =IFERROR(INDEX('Параметры типов'!$H$2:$H$209,(MATCH(Ввод!$B$5,'Справочник типов'!$A$2:$A$27,0)-1)*8+$A16),"") | H16: =IF(AND(F16<>"",F16<>"INFO"),COUNTIFS($F$12:F16,"<>INFO",$F$12:F16,"<>"),"") | I16: =IFERROR(INDEX(Ввод!$E$20:$E$27,MATCH(B16,Ввод!$A$20:$A$27,0)),D16)
A17: 6 | B17: =IFERROR(INDEX('Параметры типов'!$C$2:$C$209,(MATCH(Ввод!$B$5,'Справочник типов'!$A$2:$A$27,0)-1)*8+$A17),"") | C17: =IFERROR(INDEX('Параметры типов'!$D$2:$D$209,(MATCH(Ввод!$B$5,'Справочник типов'!$A$2:$A$27,0)-1)*8+$A17),"") | D17: =IFERROR(INDEX('Параметры типов'!$E$2:$E$209,(MATCH(Ввод!$B$5,'Справочник типов'!$A$2:$A$27,0)-1)*8+$A17),"") | E17: =IFERROR(INDEX('Параметры типов'!$F$2:$F$209,(MATCH(Ввод!$B$5,'Справочник типов'!$A$2:$A$27,0)-1)*8+$A17),"") | F17: =IFERROR(INDEX('Параметры типов'!$G$2:$G$209,(MATCH(Ввод!$B$5,'Справочник типов'!$A$2:$A$27,0)-1)*8+$A17),"") | G17: =IFERROR(INDEX('Параметры типов'!$H$2:$H$209,(MATCH(Ввод!$B$5,'Справочник типов'!$A$2:$A$27,0)-1)*8+$A17),"") | H17: =IF(AND(F17<>"",F17<>"INFO"),COUNTIFS($F$12:F17,"<>INFO",$F$12:F17,"<>"),"") | I17: =IFERROR(INDEX(Ввод!$E$20:$E$27,MATCH(B17,Ввод!$A$20:$A$27,0)),D17)
